<?xml version='1.0' encoding='utf-8'?>
<robot name="tiangong2pro_urdf" xmlns:xacro="http://wiki.ros.org/xacro">
  <link name="pelvis">
    <inertial>
      <origin xyz="-0.000979 0.00068 -0.076922" rpy="0 0 0" />
      <mass value="5.639" />
      <inertia ixx="0.018304" ixy="-0.004328" ixz="6.1e-05" iyy="0.023292" iyz="6e-05" izz="0.024244" />
    </inertial>
    <visual>
      <origin xyz="0 0 0" rpy="0 0 0" />
      <geometry>
        <mesh filename="package://tiangong2pro_urdf/meshes/pelvis.STL" />
      </geometry>
      <material name="">
        <color rgba="0.752941176470588 0.752941176470588 0.752941176470588 1" />
      </material>
    </visual>
    <collision>
      <origin xyz="0 0 0" rpy="0 0 0" />
      <geometry>
        <mesh filename="package://tiangong2pro_urdf/meshes/pelvis.STL" />
      </geometry>
    </collision>
  </link>
  <link name="hip_roll_l_link">
    <inertial>
      <origin xyz="-0.001848 0.055849 -0.036017" rpy="0 0 0" />
      <mass value="0.672983" />
      <inertia ixx="0.00102" ixy="-7e-05" ixz="3.8e-05" iyy="0.003221" iyz="0.000281" izz="0.003272" />
    </inertial>
    <visual>
      <origin xyz="0 0 0" rpy="0 0 0" />
      <geometry>
        <mesh filename="package://tiangong2pro_urdf/meshes/hip_roll_l_link.STL" />
      </geometry>
      <material name="">
        <color rgba="0.752941176470588 0.752941176470588 0.752941176470588 1" />
      </material>
    </visual>
    <collision>
      <origin xyz="0 0 0" rpy="0 0 0" />
      <geometry>
        <mesh filename="package://tiangong2pro_urdf/meshes/hip_roll_l_link.STL" />
      </geometry>
    </collision>
  </link>
  <joint name="hip_roll_l_joint" type="revolute">
    <origin xyz="0 0.028 -0.0857" rpy="0 0 0" />
    <parent link="pelvis" />
    <child link="hip_roll_l_link" />
    <axis xyz="1 0 0" />
    <limit lower="-0.7853981633974483" upper="0.7853981633974483" effort="235.0" velocity="16.755160819145562" />
  </joint>
  <link name="hip_pitch_l_link">
    <inertial>
      <origin xyz="0.001081 -8.8e-05 -0.013133" rpy="0 0 0" />
      <mass value="3.951912" />
      <inertia ixx="0.010841" ixy="-2.7e-05" ixz="0.000234" iyy="0.015597" iyz="0.000123" izz="0.00934" />
    </inertial>
    <visual>
      <origin xyz="0 0 0" rpy="0 0 0" />
      <geometry>
        <mesh filename="package://tiangong2pro_urdf/meshes/hip_pitch_l_link.STL" />
      </geometry>
      <material name="">
        <color rgba="0.752941176470588 0.752941176470588 0.752941176470588 1" />
      </material>
    </visual>
    <collision>
      <origin xyz="0 0 0" rpy="0 0 0" />
      <geometry>
        <mesh filename="package://tiangong2pro_urdf/meshes/hip_pitch_l_link.STL" />
      </geometry>
    </collision>
  </link>
  <joint name="hip_pitch_l_joint" type="revolute">
    <origin xyz="0 0.122 -0.046" rpy="0 0 0" />
    <parent link="hip_roll_l_link" />
    <child link="hip_pitch_l_link" />
    <axis xyz="0 1 0" />
    <limit lower="-2.792526803190927" upper="2.0943951023931953" effort="330.0" velocity="15.707963267948966" />
  </joint>
  <link name="hip_yaw_l_link">
    <inertial>
      <origin xyz="0.004102 -0.006542 -0.121068" rpy="0 0 0" />
      <mass value="6.670795" />
      <inertia ixx="0.049573" ixy="-0.000228" ixz="-4.4e-05" iyy="0.053307" iyz="-0.001401" izz="0.017924" />
    </inertial>
    <visual>
      <origin xyz="0 0 0" rpy="0 0 0" />
      <geometry>
        <mesh filename="package://tiangong2pro_urdf/meshes/hip_yaw_l_link.STL" />
      </geometry>
      <material name="">
        <color rgba="0.752941176470588 0.752941176470588 0.752941176470588 1" />
      </material>
    </visual>
    <collision>
      <origin xyz="0 0 0" rpy="0 0 0" />
      <geometry>
        <mesh filename="package://tiangong2pro_urdf/meshes/hip_yaw_l_link.STL" />
      </geometry>
    </collision>
  </link>
  <joint name="hip_yaw_l_joint" type="revolute">
    <origin xyz="0 -0.00015 -0.0987" rpy="0 0 0" />
    <parent link="hip_pitch_l_link" />
    <child link="hip_yaw_l_link" />
    <axis xyz="0 0 1" />
    <limit lower="-1.0471975511965976" upper="1.0471975511965976" effort="235.0" velocity="16.755160819145562" />
  </joint>
  <link name="knee_pitch_l_link">
    <inertial>
      <origin xyz="0.00018 0.001915 -0.178653" rpy="0 0 0" />
      <mass value="2.312685" />
      <inertia ixx="0.030244" ixy="-1e-05" ixz="-0.002398" iyy="0.03091" iyz="-0.000689" izz="0.002922" />
    </inertial>
    <visual>
      <origin xyz="0 0 0" rpy="0 0 0" />
      <geometry>
        <mesh filename="package://tiangong2pro_urdf/meshes/knee_pitch_l_link.STL" />
      </geometry>
      <material name="">
        <color rgba="0.752941176470588 0.752941176470588 0.752941176470588 1" />
      </material>
    </visual>
    <collision>
      <origin xyz="0 0 0" rpy="0 0 0" />
      <geometry>
        <mesh filename="package://tiangong2pro_urdf/meshes/knee_pitch_l_link.STL" />
      </geometry>
    </collision>
  </link>
  <joint name="knee_pitch_l_joint" type="revolute">
    <origin xyz="0 0.00010715 -0.3013" rpy="0 0 0" />
    <parent link="hip_yaw_l_link" />
    <child link="knee_pitch_l_link" />
    <axis xyz="0 1 0" />
    <limit lower="0.0" upper="2.3911010752322315" effort="330.0" velocity="15.707963267948966" />
  </joint>
  <link name="ankle_pitch_l_link">
    <inertial>
      <origin xyz="0.0 0.0 0.0" rpy="0 0 0" />
      <mass value="0.111609" />
      <inertia ixx="1.8e-05" ixy="0.0" ixz="0.0" iyy="1.8e-05" iyz="0.0" izz="3.2e-05" />
    </inertial>
    <visual>
      <origin xyz="0 0 0" rpy="0 0 0" />
      <geometry>
        <mesh filename="package://tiangong2pro_urdf/meshes/ankle_pitch_l_link.STL" />
      </geometry>
      <material name="">
        <color rgba="0.752941176470588 0.752941176470588 0.752941176470588 1" />
      </material>
    </visual>
    <collision>
      <origin xyz="0 0 0" rpy="0 0 0" />
      <geometry>
        <mesh filename="package://tiangong2pro_urdf/meshes/ankle_pitch_l_link.STL" />
      </geometry>
    </collision>
  </link>
  <joint name="ankle_pitch_l_joint" type="revolute">
    <origin xyz="0 0 -0.4" rpy="0 0 0" />
    <parent link="knee_pitch_l_link" />
    <child link="ankle_pitch_l_link" />
    <axis xyz="0 1 0" />
    <limit lower="-1.2217304763960306" upper="0.5235987755982988" effort="55.0" velocity="14.137166941154069" />
  </joint>
  <link name="ankle_roll_l_link">
    <inertial>
      <origin xyz="0.021235 0.0 -0.032883" rpy="0 0 0" />
      <mass value="1.017381" />
      <inertia ixx="0.001028" ixy="0.0" ixz="0.000622" iyy="0.006055" iyz="0.0" izz="0.00624" />
    </inertial>
    <visual>
      <origin xyz="0 0 0" rpy="0 0 0" />
      <geometry>
        <mesh filename="package://tiangong2pro_urdf/meshes/ankle_roll_l_link.STL" />
      </geometry>
      <material name="">
        <color rgba="0.752941176470588 0.752941176470588 0.752941176470588 1" />
      </material>
    </visual>
    <collision>
      <origin xyz="0 0 0" rpy="0 0 0" />
      <geometry>
        <mesh filename="package://tiangong2pro_urdf/meshes/ankle_roll_l_link.STL" />
      </geometry>
    </collision>
  </link>
  <joint name="ankle_roll_l_joint" type="revolute">
    <origin xyz="0 0 0" rpy="0 0 0" />
    <parent link="ankle_pitch_l_link" />
    <child link="ankle_roll_l_link" />
    <axis xyz="1 0 0" />
    <limit lower="-0.5235987755982988" upper="0.5235987755982988" effort="55.0" velocity="14.137166941154069" />
  </joint>
  <link name="hip_roll_r_link">
    <inertial>
      <origin xyz="-0.001848 -0.055849 -0.036017" rpy="0 0 0" />
      <mass value="0.672983" />
      <inertia ixx="0.00102" ixy="7e-05" ixz="3.8e-05" iyy="0.003221" iyz="-0.000281" izz="0.003272" />
    </inertial>
    <visual>
      <origin xyz="0 0 0" rpy="0 0 0" />
      <geometry>
        <mesh filename="package://tiangong2pro_urdf/meshes/hip_roll_r_link.STL" />
      </geometry>
      <material name="">
        <color rgba="0.752941176470588 0.752941176470588 0.752941176470588 1" />
      </material>
    </visual>
    <collision>
      <origin xyz="0 0 0" rpy="0 0 0" />
      <geometry>
        <mesh filename="package://tiangong2pro_urdf/meshes/hip_roll_r_link.STL" />
      </geometry>
    </collision>
  </link>
  <joint name="hip_roll_r_joint" type="revolute">
    <origin xyz="0 -0.028 -0.0857" rpy="0 0 0" />
    <parent link="pelvis" />
    <child link="hip_roll_r_link" />
    <axis xyz="1 0 0" />
    <limit lower="-0.7853981633974483" upper="0.7853981633974483" effort="235.0" velocity="16.755160819145562" />
  </joint>
  <link name="hip_pitch_r_link">
    <inertial>
      <origin xyz="0.001081 8.8e-05 -0.013133" rpy="0 0 0" />
      <mass value="3.951912" />
      <inertia ixx="0.010841" ixy="2.7e-05" ixz="0.000234" iyy="0.015597" iyz="-0.000123" izz="0.00934" />
    </inertial>
    <visual>
      <origin xyz="0 0 0" rpy="0 0 0" />
      <geometry>
        <mesh filename="package://tiangong2pro_urdf/meshes/hip_pitch_r_link.STL" />
      </geometry>
      <material name="">
        <color rgba="0.752941176470588 0.752941176470588 0.752941176470588 1" />
      </material>
    </visual>
    <collision>
      <origin xyz="0 0 0" rpy="0 0 0" />
      <geometry>
        <mesh filename="package://tiangong2pro_urdf/meshes/hip_pitch_r_link.STL" />
      </geometry>
    </collision>
  </link>
  <joint name="hip_pitch_r_joint" type="revolute">
    <origin xyz="0 -0.122 -0.046" rpy="0 0 0" />
    <parent link="hip_roll_r_link" />
    <child link="hip_pitch_r_link" />
    <axis xyz="0 1 0" />
    <limit lower="-2.792526803190927" upper="2.0943951023931953" effort="330.0" velocity="15.707963267948966" />
  </joint>
  <link name="hip_yaw_r_link">
    <inertial>
      <origin xyz="0.004102 0.006542 -0.121068" rpy="0 0 0" />
      <mass value="6.670795" />
      <inertia ixx="0.049573" ixy="0.000228" ixz="-4.4e-05" iyy="0.053307" iyz="0.001401" izz="0.017924" />
    </inertial>
    <visual>
      <origin xyz="0 0 0" rpy="0 0 0" />
      <geometry>
        <mesh filename="package://tiangong2pro_urdf/meshes/hip_yaw_r_link.STL" />
      </geometry>
      <material name="">
        <color rgba="0.752941176470588 0.752941176470588 0.752941176470588 1" />
      </material>
    </visual>
    <collision>
      <origin xyz="0 0 0" rpy="0 0 0" />
      <geometry>
        <mesh filename="package://tiangong2pro_urdf/meshes/hip_yaw_r_link.STL" />
      </geometry>
    </collision>
  </link>
  <joint name="hip_yaw_r_joint" type="revolute">
    <origin xyz="0 0 -0.0987" rpy="0 0 0" />
    <parent link="hip_pitch_r_link" />
    <child link="hip_yaw_r_link" />
    <axis xyz="0 0 1" />
    <limit lower="-1.0471975511965976" upper="1.0471975511965976" effort="235.0" velocity="16.755160819145562" />
  </joint>
  <link name="knee_pitch_r_link">
    <inertial>
      <origin xyz="0.00018 -0.001915 -0.178653" rpy="0 0 0" />
      <mass value="2.312685" />
      <inertia ixx="0.030244" ixy="1e-05" ixz="-0.002398" iyy="0.03091" iyz="0.000689" izz="0.002922" />
    </inertial>
    <visual>
      <origin xyz="0 0 0" rpy="0 0 0" />
      <geometry>
        <mesh filename="package://tiangong2pro_urdf/meshes/knee_pitch_r_link.STL" />
      </geometry>
      <material name="">
        <color rgba="0.752941176470588 0.752941176470588 0.752941176470588 1" />
      </material>
    </visual>
    <collision>
      <origin xyz="0 0 0" rpy="0 0 0" />
      <geometry>
        <mesh filename="package://tiangong2pro_urdf/meshes/knee_pitch_r_link.STL" />
      </geometry>
    </collision>
  </link>
  <joint name="knee_pitch_r_joint" type="revolute">
    <origin xyz="0 9.9938E-05 -0.3013" rpy="0 0 0" />
    <parent link="hip_yaw_r_link" />
    <child link="knee_pitch_r_link" />
    <axis xyz="0 1 0" />
    <limit lower="0.0" upper="2.3911010752322315" effort="330.0" velocity="15.707963267948966" />
  </joint>
  <link name="ankle_pitch_r_link">
    <inertial>
      <origin xyz="0.0 0.0 0.0" rpy="0 0 0" />
      <mass value="0.111609" />
      <inertia ixx="1.8e-05" ixy="0.0" ixz="0.0" iyy="1.8e-05" iyz="0.0" izz="3.2e-05" />
    </inertial>
    <visual>
      <origin xyz="0 0 0" rpy="0 0 0" />
      <geometry>
        <mesh filename="package://tiangong2pro_urdf/meshes/ankle_pitch_r_link.STL" />
      </geometry>
      <material name="">
        <color rgba="0.752941176470588 0.752941176470588 0.752941176470588 1" />
      </material>
    </visual>
    <collision>
      <origin xyz="0 0 0" rpy="0 0 0" />
      <geometry>
        <mesh filename="package://tiangong2pro_urdf/meshes/ankle_pitch_r_link.STL" />
      </geometry>
    </collision>
  </link>
  <joint name="ankle_pitch_r_joint" type="revolute">
    <origin xyz="0 0.00099989 -0.4" rpy="0 0 0" />
    <parent link="knee_pitch_r_link" />
    <child link="ankle_pitch_r_link" />
    <axis xyz="0 1 0" />
    <limit lower="-1.2217304763960306" upper="0.5235987755982988" effort="55.0" velocity="14.137166941154069" />
  </joint>
  <link name="ankle_roll_r_link">
    <inertial>
      <origin xyz="0.021235 0.0 -0.032883" rpy="0 0 0" />
      <mass value="1.017381" />
      <inertia ixx="0.001028" ixy="0.0" ixz="0.000622" iyy="0.006055" iyz="0.0" izz="0.00624" />
    </inertial>
    <visual>
      <origin xyz="0 0 0" rpy="0 0 0" />
      <geometry>
        <mesh filename="package://tiangong2pro_urdf/meshes/ankle_roll_r_link.STL" />
      </geometry>
      <material name="">
        <color rgba="0.752941176470588 0.752941176470588 0.752941176470588 1" />
      </material>
    </visual>
    <collision>
      <origin xyz="0 0 0" rpy="0 0 0" />
      <geometry>
        <mesh filename="package://tiangong2pro_urdf/meshes/ankle_roll_r_link.STL" />
      </geometry>
    </collision>
  </link>
  <joint name="ankle_roll_r_joint" type="revolute">
    <origin xyz="0 0 0" rpy="0 0 0" />
    <parent link="ankle_pitch_r_link" />
    <child link="ankle_roll_r_link" />
    <axis xyz="1 0 0" />
    <limit lower="-0.5235987755982988" upper="0.5235987755982988" effort="55.0" velocity="14.137166941154069" />
  </joint>
  <link name="waist_yaw_link">
    <inertial>
      <origin xyz="-0.000568 0.00056 0.231488" rpy="0 0 0" />
      <mass value="22.0" />
      <inertia ixx="0.429034" ixy="0.000293" ixz="-0.003462" iyy="0.379055" iyz="0.000237" izz="0.177142" />
    </inertial>
    <visual>
      <origin xyz="0 0 0" rpy="0 0 0" />
      <geometry>
        <mesh filename="package://tiangong2pro_urdf/meshes/waist_yaw_link.STL" />
      </geometry>
      <material name="">
        <color rgba="0.752941176470588 0.752941176470588 0.752941176470588 1" />
      </material>
    </visual>
    <collision>
      <origin xyz="0 0 0" rpy="0 0 0" />
      <geometry>
        <mesh filename="package://tiangong2pro_urdf/meshes/waist_yaw_link.STL" />
      </geometry>
    </collision>
  </link>
  <joint name="body_yaw_joint" type="revolute">
    <origin xyz="0 0 0" rpy="0 0 0" />
    <parent link="pelvis" />
    <child link="waist_yaw_link" />
    <axis xyz="0 0 1" />
    <limit lower="-2.9670597283903604" upper="3.141592653589793" effort="91.0" velocity="9.215338450530059" />
  </joint>
  <link name="head_yaw_link">
    <inertial>
      <origin xyz="-0.000202 0.000454 0.007248" rpy="0 0 0" />
      <mass value="0.088397" />
      <inertia ixx="9.5e-05" ixy="-1e-06" ixz="-3e-06" iyy="7.6e-05" iyz="-3e-06" izz="0.000106" />
    </inertial>
    <visual>
      <origin xyz="0 0 0" rpy="0 0 0" />
      <geometry>
        <mesh filename="package://tiangong2pro_urdf/meshes/head_yaw_link.STL" />
      </geometry>
      <material name="">
        <color rgba="0.752941176470588 0.752941176470588 0.752941176470588 1" />
      </material>
    </visual>
    <collision>
      <origin xyz="0 0 0" rpy="0 0 0" />
      <geometry>
        <mesh filename="package://tiangong2pro_urdf/meshes/head_yaw_link.STL" />
      </geometry>
    </collision>
  </link>
  <joint name="head_yaw_joint" type="revolute">
    <origin xyz="-0.002 0 0.56508" rpy="0 0 0" />
    <parent link="waist_yaw_link" />
    <child link="head_yaw_link" />
    <axis xyz="0 0 1" />
    <limit lower="-1.5707963267948966" upper="1.5707963267948966" effort="6.3" velocity="7.5398223686155035" />
  </joint>
  <link name="head_pitch_link">
    <inertial>
      <origin xyz="-0.000274 0.004118 2.3e-05" rpy="0 0 0" />
      <mass value="0.23046" />
      <inertia ixx="9.2e-05" ixy="1e-06" ixz="-1e-06" iyy="5.4e-05" iyz="0.0" izz="9.5e-05" />
    </inertial>
    <visual>
      <origin xyz="0 0 0" rpy="0 0 0" />
      <geometry>
        <mesh filename="package://tiangong2pro_urdf/meshes/head_pitch_link.STL" />
      </geometry>
      <material name="">
        <color rgba="0.752941176470588 0.752941176470588 0.752941176470588 1" />
      </material>
    </visual>
    <collision>
      <origin xyz="0 0 0" rpy="0 0 0" />
      <geometry>
        <mesh filename="package://tiangong2pro_urdf/meshes/head_pitch_link.STL" />
      </geometry>
    </collision>
  </link>
  <joint name="head_pitch_joint" type="revolute">
    <origin xyz="0.01455 0 0.0304" rpy="0 0.2618 0" />
    <parent link="head_yaw_link" />
    <child link="head_pitch_link" />
    <axis xyz="0 1 0" />
    <limit lower="-0.4363323129985824" upper="0.4363323129985824" effort="6.3" velocity="7.5398223686155035" />
  </joint>
  <link name="head_roll_link">
    <inertial>
      <origin xyz="0.022467 0.001208 0.053952" rpy="0 0 0" />
      <mass value="0.844627" />
      <inertia ixx="0.00235" ixy="3.8e-05" ixz="0.000436" iyy="0.003365" iyz="6e-06" izz="0.002875" />
    </inertial>
    <visual>
      <origin xyz="0 0 0" rpy="0 0 0" />
      <geometry>
        <mesh filename="package://tiangong2pro_urdf/meshes/head_roll_link.STL" />
      </geometry>
      <material name="">
        <color rgba="0.752941176470588 0.752941176470588 0.752941176470588 1" />
      </material>
    </visual>
    <collision>
      <origin xyz="0 0 0" rpy="0 0 0" />
      <geometry>
        <mesh filename="package://tiangong2pro_urdf/meshes/head_roll_link.STL" />
      </geometry>
    </collision>
  </link>
  <joint name="head_roll_joint" type="revolute">
    <origin xyz="0 0 0" rpy="0 0 0" />
    <parent link="head_pitch_link" />
    <child link="head_roll_link" />
    <axis xyz="1 0 0" />
    <limit lower="-0.4537856055185257" upper="0.4537856055185257" effort="6.3" velocity="7.5398223686155035" />
  </joint>
  <link name="ob_camera_head_link">
    <inertial>
      <origin xyz="0.010986 -0.000307 -0.016475" rpy="0 0 0" />
      <mass value="0.1" />
      <inertia ixx="1.6e-05" ixy="0.0" ixz="0.0" iyy="8e-05" iyz="0.0" izz="7.7e-05" />
    </inertial>
    <visual>
      <origin xyz="0 0 0" rpy="0 0 0" />
      <geometry>
        <mesh filename="package://tiangong2pro_urdf/meshes/camera_head_link.STL" />
      </geometry>
      <material name="">
        <color rgba="0.752941176470588 0.752941176470588 0.752941176470588 1" />
      </material>
    </visual>
    <collision>
      <origin xyz="0 0 0" rpy="0 0 0" />
      <geometry>
        <mesh filename="package://tiangong2pro_urdf/meshes/camera_head_link.STL" />
      </geometry>
    </collision>
  </link>
  <joint name="camera_head_joint" type="fixed">
    <origin xyz="0.075191 0.010935 0.074436" rpy="-1.8326 0 -1.5708" />
    <parent link="head_roll_link" />
    <child link="ob_camera_head_link" />
    <axis xyz="0 0 0" />
  </joint>
  <link name="shoulder_pitch_l_link">
    <inertial>
      <origin xyz="0.007494 0.064184 -2e-05" rpy="0 0 0" />
      <mass value="1.032698" />
      <inertia ixx="0.001025" ixy="-2.7e-05" ixz="-1e-06" iyy="0.001078" iyz="0.0" izz="0.001247" />
    </inertial>
    <visual>
      <origin xyz="0 0 0" rpy="0 0 0" />
      <geometry>
        <mesh filename="package://tiangong2pro_urdf/meshes/shoulder_pitch_l_link.STL" />
      </geometry>
      <material name="">
        <color rgba="0.752941176470588 0.752941176470588 0.752941176470588 1" />
      </material>
    </visual>
    <collision>
      <origin xyz="0 0 0" rpy="0 0 0" />
      <geometry>
        <mesh filename="package://tiangong2pro_urdf/meshes/shoulder_pitch_l_link.STL" />
      </geometry>
    </collision>
  </link>
  <joint name="shoulder_pitch_l_joint" type="revolute">
    <origin xyz="0 0.1444 0.37712" rpy="0.087266 0 0" />
    <parent link="waist_yaw_link" />
    <child link="shoulder_pitch_l_link" />
    <axis xyz="0 1 0" />
    <limit lower="-2.9670597283903604" upper="2.9670597283903604" effort="91.0" velocity="9.215338450530059" />
  </joint>
  <link name="shoulder_roll_l_link">
    <inertial>
      <origin xyz="0.002389 0.002259 -0.048236" rpy="0 0 0" />
      <mass value="0.440997" />
      <inertia ixx="0.001001" ixy="-4e-06" ixz="-2.5e-05" iyy="0.001313" iyz="-1.4e-05" izz="0.000911" />
    </inertial>
    <visual>
      <origin xyz="0 0 0" rpy="0 0 0" />
      <geometry>
        <mesh filename="package://tiangong2pro_urdf/meshes/shoulder_roll_l_link.STL" />
      </geometry>
      <material name="">
        <color rgba="0.752941176470588 0.752941176470588 0.752941176470588 1" />
      </material>
    </visual>
    <collision>
      <origin xyz="0 0 0" rpy="0 0 0" />
      <geometry>
        <mesh filename="package://tiangong2pro_urdf/meshes/shoulder_roll_l_link.STL" />
      </geometry>
    </collision>
  </link>
  <joint name="shoulder_roll_l_joint" type="revolute">
    <origin xyz="0 0.068 0" rpy="0 0 0" />
    <parent link="shoulder_pitch_l_link" />
    <child link="shoulder_roll_l_link" />
    <axis xyz="1 0 0" />
    <limit lower="-0.2617993877991494" upper="2.6179938779914944" effort="95.0" velocity="3.979350694547071" />
  </joint>
  <link name="shoulder_yaw_l_link">
    <inertial>
      <origin xyz="0.008319 0.002686 -0.112525" rpy="0 0 0" />
      <mass value="1.365033" />
      <inertia ixx="0.009637" ixy="-5.7e-05" ixz="0.00095" iyy="0.0096" iyz="0.000339" izz="0.001331" />
    </inertial>
    <visual>
      <origin xyz="0 0 0" rpy="0 0 0" />
      <geometry>
        <mesh filename="package://tiangong2pro_urdf/meshes/shoulder_yaw_l_link.STL" />
      </geometry>
      <material name="">
        <color rgba="0.752941176470588 0.752941176470588 0.752941176470588 1" />
      </material>
    </visual>
    <collision>
      <origin xyz="0 0 0" rpy="0 0 0" />
      <geometry>
        <mesh filename="package://tiangong2pro_urdf/meshes/shoulder_yaw_l_link.STL" />
      </geometry>
    </collision>
  </link>
  <joint name="shoulder_yaw_l_joint" type="revolute">
    <origin xyz="0 0 -0.1025" rpy="0 0 0" />
    <parent link="shoulder_roll_l_link" />
    <child link="shoulder_yaw_l_link" />
    <axis xyz="0 0 1" />
    <limit lower="-2.9670597283903604" upper="2.9670597283903604" effort="35.0" velocity="5.235987755982989" />
  </joint>
  <link name="elbow_pitch_l_link">
    <inertial>
      <origin xyz="-0.014694 -7.2e-05 -0.026081" rpy="0 0 0" />
      <mass value="0.246311" />
      <inertia ixx="0.000381" ixy="1e-06" ixz="-1.2e-05" iyy="0.000222" iyz="2e-06" izz="0.000401" />
    </inertial>
    <visual>
      <origin xyz="0 0 0" rpy="0 0 0" />
      <geometry>
        <mesh filename="package://tiangong2pro_urdf/meshes/elbow_pitch_l_link.STL" />
      </geometry>
      <material name="">
        <color rgba="0.752941176470588 0.752941176470588 0.752941176470588 1" />
      </material>
    </visual>
    <collision>
      <origin xyz="0 0 0" rpy="0 0 0" />
      <geometry>
        <mesh filename="package://tiangong2pro_urdf/meshes/elbow_pitch_l_link.STL" />
      </geometry>
    </collision>
  </link>
  <joint name="elbow_pitch_l_joint" type="revolute">
    <origin xyz="0.02 0 -0.1975" rpy="0 0 0" />
    <parent link="shoulder_yaw_l_link" />
    <child link="elbow_pitch_l_link" />
    <axis xyz="0 1 0" />
    <limit lower="-2.6179938779914944" upper="0.2617993877991494" effort="35.0" velocity="5.235987755982989" />
  </joint>
  <link name="elbow_yaw_l_link">
    <inertial>
      <origin xyz="0.000158 0.001503 -0.069535" rpy="0 0 0" />
      <mass value="0.986828" />
      <inertia ixx="0.003108" ixy="-1e-06" ixz="8e-06" iyy="0.003035" iyz="8.9e-05" izz="0.00058" />
    </inertial>
    <visual>
      <origin xyz="0 0 0" rpy="0 0 0" />
      <geometry>
        <mesh filename="package://tiangong2pro_urdf/meshes/elbow_yaw_l_link.STL" />
      </geometry>
      <material name="">
        <color rgba="0.752941176470588 0.752941176470588 0.752941176470588 1" />
      </material>
    </visual>
    <collision>
      <origin xyz="0 0 0" rpy="0 0 0" />
      <geometry>
        <mesh filename="package://tiangong2pro_urdf/meshes/elbow_yaw_l_link.STL" />
      </geometry>
    </collision>
  </link>
  <joint name="elbow_yaw_l_joint" type="revolute">
    <origin xyz="-0.02 0 -0.0543" rpy="0 0 0" />
    <parent link="elbow_pitch_l_link" />
    <child link="elbow_yaw_l_link" />
    <axis xyz="0 0 1" />
    <limit lower="-2.9670597283903604" upper="2.9670597283903604" effort="24.0" velocity="10.471975511965978" />
  </joint>
  <link name="wrist_pitch_l_link">
    <inertial>
      <origin xyz="0.005362 0.00064 -0.018812" rpy="0 0 0" />
      <mass value="0.262007" />
      <inertia ixx="7.1e-05" ixy="-3e-06" ixz="-2e-06" iyy="0.000112" iyz="-3e-06" izz="0.000111" />
    </inertial>
    <visual>
      <origin xyz="0 0 0" rpy="0 0 0" />
      <geometry>
        <mesh filename="package://tiangong2pro_urdf/meshes/wrist_pitch_l_link.STL" />
      </geometry>
      <material name="">
        <color rgba="0.752941176470588 0.752941176470588 0.752941176470588 1" />
      </material>
    </visual>
    <collision>
      <origin xyz="0 0 0" rpy="0 0 0" />
      <geometry>
        <mesh filename="package://tiangong2pro_urdf/meshes/wrist_pitch_l_link.STL" />
      </geometry>
    </collision>
  </link>
  <joint name="wrist_pitch_l_joint" type="revolute">
    <origin xyz="0 0 -0.1887" rpy="0 0 0" />
    <parent link="elbow_yaw_l_link" />
    <child link="wrist_pitch_l_link" />
    <axis xyz="0 1 0" />
    <limit lower="-0.7853981633974483" upper="1.0471975511965976" effort="6.3" velocity="7.5398223686155035" />
  </joint>
  <link name="wrist_roll_l_link">
    <inertial>
      <origin xyz="0.000801 8.4e-05 -0.029302" rpy="0 0 0" />
      <mass value="0.131751" />
      <inertia ixx="6.9e-05" ixy="0.0" ixz="-1e-06" iyy="0.000116" iyz="0.0" izz="0.00011" />
    </inertial>
    <visual>
      <origin xyz="0 0 0" rpy="0 0 0" />
      <geometry>
        <mesh filename="package://tiangong2pro_urdf/meshes/wrist_roll_l_link.STL" />
      </geometry>
      <material name="">
        <color rgba="0.752941176470588 0.752941176470588 0.752941176470588 1" />
      </material>
    </visual>
    <collision>
      <origin xyz="0 0 0" rpy="0 0 0" />
      <geometry>
        <mesh filename="package://tiangong2pro_urdf/meshes/wrist_roll_l_link.STL" />
      </geometry>
    </collision>
  </link>
  <joint name="wrist_roll_l_joint" type="revolute">
    <origin xyz="0 0 -0.02" rpy="0 0 0" />
    <parent link="wrist_pitch_l_link" />
    <child link="wrist_roll_l_link" />
    <axis xyz="1 0 0" />
    <limit lower="-1.6580627893946132" upper="1.3089969389957472" effort="6.3" velocity="7.5398223686155035" />
  </joint>
  <link name="left_tcp_link">
    <inertial>
      <origin xyz="0.000415 0.000651 0.017052" rpy="0 0 0" />
      <mass value="0.218186" />
      <inertia ixx="8.6e-05" ixy="-2e-06" ixz="-1e-06" iyy="8.4e-05" iyz="-1e-06" izz="0.000109" />
    </inertial>
    <visual>
      <origin xyz="0 0 0" rpy="0 0 0" />
      <geometry>
        <mesh filename="package://tiangong2pro_urdf/meshes/left_tcp_link.STL" />
      </geometry>
      <material name="">
        <color rgba="0.752941176470588 0.752941176470588 0.752941176470588 1" />
      </material>
    </visual>
    <collision>
      <origin xyz="0 0 0" rpy="0 0 0" />
      <geometry>
        <mesh filename="package://tiangong2pro_urdf/meshes/left_tcp_link.STL" />
      </geometry>
    </collision>
  </link>
  <joint name="left_tcp_joint" type="fixed">
    <origin xyz="0 0 -0.0848" rpy="0 0 0" />
    <parent link="wrist_roll_l_link" />
    <child link="left_tcp_link" />
    <axis xyz="0 0 0" />
  </joint>
  <link name="shoulder_pitch_r_link">
    <inertial>
      <origin xyz="0.007494 -0.064184 -2e-05" rpy="0 0 0" />
      <mass value="1.032698" />
      <inertia ixx="0.001025" ixy="2.7e-05" ixz="-1e-06" iyy="0.001078" iyz="0.0" izz="0.001247" />
    </inertial>
    <visual>
      <origin xyz="0 0 0" rpy="0 0 0" />
      <geometry>
        <mesh filename="package://tiangong2pro_urdf/meshes/shoulder_pitch_r_link.STL" />
      </geometry>
      <material name="">
        <color rgba="0.752941176470588 0.752941176470588 0.752941176470588 1" />
      </material>
    </visual>
    <collision>
      <origin xyz="0 0 0" rpy="0 0 0" />
      <geometry>
        <mesh filename="package://tiangong2pro_urdf/meshes/shoulder_pitch_r_link.STL" />
      </geometry>
    </collision>
  </link>
  <joint name="shoulder_pitch_r_joint" type="revolute">
    <origin xyz="0 -0.1444 0.37712" rpy="-0.087266 0 0" />
    <parent link="waist_yaw_link" />
    <child link="shoulder_pitch_r_link" />
    <axis xyz="0 1 0" />
    <limit lower="-2.9670597283903604" upper="2.9670597283903604" effort="91.0" velocity="9.215338450530059" />
  </joint>
  <link name="shoulder_roll_r_link">
    <inertial>
      <origin xyz="0.002389 -0.002259 -0.048236" rpy="0 0 0" />
      <mass value="0.440997" />
      <inertia ixx="0.001001" ixy="4e-06" ixz="-2.5e-05" iyy="0.001313" iyz="1.4e-05" izz="0.000911" />
    </inertial>
    <visual>
      <origin xyz="0 0 0" rpy="0 0 0" />
      <geometry>
        <mesh filename="package://tiangong2pro_urdf/meshes/shoulder_roll_r_link.STL" />
      </geometry>
      <material name="">
        <color rgba="0.752941176470588 0.752941176470588 0.752941176470588 1" />
      </material>
    </visual>
    <collision>
      <origin xyz="0 0 0" rpy="0 0 0" />
      <geometry>
        <mesh filename="package://tiangong2pro_urdf/meshes/shoulder_roll_r_link.STL" />
      </geometry>
    </collision>
  </link>
  <joint name="shoulder_roll_r_joint" type="revolute">
    <origin xyz="0 -0.068 0" rpy="0 0 0" />
    <parent link="shoulder_pitch_r_link" />
    <child link="shoulder_roll_r_link" />
    <axis xyz="1 0 0" />
    <limit lower="-2.6179938779914944" upper="0.2617993877991494" effort="95.0" velocity="3.979350694547071" />
  </joint>
  <link name="shoulder_yaw_r_link">
    <inertial>
      <origin xyz="0.008319 -0.002686 -0.112525" rpy="0 0 0" />
      <mass value="1.365033" />
      <inertia ixx="0.009637" ixy="5.7e-05" ixz="0.00095" iyy="0.0096" iyz="-0.000339" izz="0.001331" />
    </inertial>
    <visual>
      <origin xyz="0 0 0" rpy="0 0 0" />
      <geometry>
        <mesh filename="package://tiangong2pro_urdf/meshes/shoulder_yaw_r_link.STL" />
      </geometry>
      <material name="">
        <color rgba="0.752941176470588 0.752941176470588 0.752941176470588 1" />
      </material>
    </visual>
    <collision>
      <origin xyz="0 0 0" rpy="0 0 0" />
      <geometry>
        <mesh filename="package://tiangong2pro_urdf/meshes/shoulder_yaw_r_link.STL" />
      </geometry>
    </collision>
  </link>
  <joint name="shoulder_yaw_r_joint" type="revolute">
    <origin xyz="0 0 -0.1025" rpy="0 0 0" />
    <parent link="shoulder_roll_r_link" />
    <child link="shoulder_yaw_r_link" />
    <axis xyz="0 0 1" />
    <limit lower="-2.9670597283903604" upper="2.9670597283903604" effort="35.0" velocity="5.235987755982989" />
  </joint>
  <link name="elbow_pitch_r_link">
    <inertial>
      <origin xyz="-0.014694 7.2e-05 -0.026081" rpy="0 0 0" />
      <mass value="0.246311" />
      <inertia ixx="0.000381" ixy="-1e-06" ixz="-1.2e-05" iyy="0.000222" iyz="-2e-06" izz="0.000401" />
    </inertial>
    <visual>
      <origin xyz="0 0 0" rpy="0 0 0" />
      <geometry>
        <mesh filename="package://tiangong2pro_urdf/meshes/elbow_pitch_r_link.STL" />
      </geometry>
      <material name="">
        <color rgba="0.752941176470588 0.752941176470588 0.752941176470588 1" />
      </material>
    </visual>
    <collision>
      <origin xyz="0 0 0" rpy="0 0 0" />
      <geometry>
        <mesh filename="package://tiangong2pro_urdf/meshes/elbow_pitch_r_link.STL" />
      </geometry>
    </collision>
  </link>
  <joint name="elbow_pitch_r_joint" type="revolute">
    <origin xyz="0.02 0 -0.1975" rpy="0 0 0" />
    <parent link="shoulder_yaw_r_link" />
    <child link="elbow_pitch_r_link" />
    <axis xyz="0 1 0" />
    <limit lower="-2.6179938779914944" upper="0.2617993877991494" effort="35.0" velocity="5.235987755982989" />
  </joint>
  <link name="elbow_yaw_r_link">
    <inertial>
      <origin xyz="0.000158 -0.001503 -0.069535" rpy="0 0 0" />
      <mass value="0.986828" />
      <inertia ixx="0.003108" ixy="1e-06" ixz="8e-06" iyy="0.003035" iyz="-8.9e-05" izz="0.00058" />
    </inertial>
    <visual>
      <origin xyz="0 0 0" rpy="0 0 0" />
      <geometry>
        <mesh filename="package://tiangong2pro_urdf/meshes/elbow_yaw_r_link.STL" />
      </geometry>
      <material name="">
        <color rgba="0.752941176470588 0.752941176470588 0.752941176470588 1" />
      </material>
    </visual>
    <collision>
      <origin xyz="0 0 0" rpy="0 0 0" />
      <geometry>
        <mesh filename="package://tiangong2pro_urdf/meshes/elbow_yaw_r_link.STL" />
      </geometry>
    </collision>
  </link>
  <joint name="elbow_yaw_r_joint" type="revolute">
    <origin xyz="-0.02 0 -0.0543" rpy="0 0 0" />
    <parent link="elbow_pitch_r_link" />
    <child link="elbow_yaw_r_link" />
    <axis xyz="0 0 1" />
    <limit lower="-2.9670597283903604" upper="2.9670597283903604" effort="24.0" velocity="10.471975511965978" />
  </joint>
  <link name="wrist_pitch_r_link">
    <inertial>
      <origin xyz="0.005362 -0.00064 -0.018812" rpy="0 0 0" />
      <mass value="0.262007" />
      <inertia ixx="7.1e-05" ixy="3e-06" ixz="-2e-06" iyy="0.000112" iyz="3e-06" izz="0.000111" />
    </inertial>
    <visual>
      <origin xyz="0 0 0" rpy="0 0 0" />
      <geometry>
        <mesh filename="package://tiangong2pro_urdf/meshes/wrist_pitch_r_link.STL" />
      </geometry>
      <material name="">
        <color rgba="0.752941176470588 0.752941176470588 0.752941176470588 1" />
      </material>
    </visual>
    <collision>
      <origin xyz="0 0 0" rpy="0 0 0" />
      <geometry>
        <mesh filename="package://tiangong2pro_urdf/meshes/wrist_pitch_r_link.STL" />
      </geometry>
    </collision>
  </link>
  <joint name="wrist_pitch_r_joint" type="revolute">
    <origin xyz="0 0 -0.1887" rpy="0 0 0" />
    <parent link="elbow_yaw_r_link" />
    <child link="wrist_pitch_r_link" />
    <axis xyz="0 1 0" />
    <limit lower="-0.7853981633974483" upper="1.0471975511965976" effort="6.3" velocity="7.5398223686155035" />
  </joint>
  <link name="wrist_roll_r_link">
    <inertial>
      <origin xyz="0.000801 -8.4e-05 -0.029302" rpy="0 0 0" />
      <mass value="0.131751" />
      <inertia ixx="6.9e-05" ixy="0.0" ixz="-1e-06" iyy="0.000116" iyz="0.0" izz="0.00011" />
    </inertial>
    <visual>
      <origin xyz="0 0 0" rpy="0 0 0" />
      <geometry>
        <mesh filename="package://tiangong2pro_urdf/meshes/wrist_roll_r_link.STL" />
      </geometry>
      <material name="">
        <color rgba="0.752941176470588 0.752941176470588 0.752941176470588 1" />
      </material>
    </visual>
    <collision>
      <origin xyz="0 0 0" rpy="0 0 0" />
      <geometry>
        <mesh filename="package://tiangong2pro_urdf/meshes/wrist_roll_r_link.STL" />
      </geometry>
    </collision>
  </link>
  <joint name="wrist_roll_r_joint" type="revolute">
    <origin xyz="0 0 -0.02" rpy="0 0 0" />
    <parent link="wrist_pitch_r_link" />
    <child link="wrist_roll_r_link" />
    <axis xyz="1 0 0" />
    <limit lower="-1.3089969389957472" upper="1.6580627893946132" effort="6.3" velocity="7.5398223686155035" />
  </joint>
  <link name="right_tcp_link">
    <inertial>
      <origin xyz="0.000415 -0.000651 0.017052" rpy="0 0 0" />
      <mass value="0.218186" />
      <inertia ixx="8.6e-05" ixy="2e-06" ixz="-1e-06" iyy="8.4e-05" iyz="1e-06" izz="0.000109" />
    </inertial>
    <visual>
      <origin xyz="0 0 0" rpy="0 0 0" />
      <geometry>
        <mesh filename="package://tiangong2pro_urdf/meshes/right_tcp_link.STL" />
      </geometry>
      <material name="">
        <color rgba="0.752941176470588 0.752941176470588 0.752941176470588 1" />
      </material>
    </visual>
    <collision>
      <origin xyz="0 0 0" rpy="0 0 0" />
      <geometry>
        <mesh filename="package://tiangong2pro_urdf/meshes/right_tcp_link.STL" />
      </geometry>
    </collision>
  </link>
  <joint name="right_tcp_joint" type="fixed">
    <origin xyz="0 0 -0.0848" rpy="0 0 0" />
    <parent link="wrist_roll_r_link" />
    <child link="right_tcp_link" />
    <axis xyz="0 0 0" />
  </joint>
  <link name="ob_camera_waist_link">
    <inertial>
      <origin xyz="0.023316 0.000241 -0.013373" rpy="0 0 0" />
      <mass value="0.1" />
      <inertia ixx="1.5e-05" ixy="1e-06" ixz="-1e-06" iyy="0.000127" iyz="0.0" izz="0.000127" />
    </inertial>
    <visual>
      <origin xyz="0 0 0" rpy="0 0 0" />
      <geometry>
        <mesh filename="package://tiangong2pro_urdf/meshes/camera_body_front_link.STL" />
      </geometry>
      <material name="">
        <color rgba="0.752941176470588 0.752941176470588 0.752941176470588 1" />
      </material>
    </visual>
    <collision>
      <origin xyz="0 0 0" rpy="0 0 0" />
      <geometry>
        <mesh filename="package://tiangong2pro_urdf/meshes/camera_body_front_link.STL" />
      </geometry>
    </collision>
  </link>
  <joint name="camera_body_front_joint" type="fixed">
    <origin xyz="0.090583 0.02375 0.039012" rpy="-2.1468 0 -1.5708" />
    <parent link="waist_yaw_link" />
    <child link="ob_camera_waist_link" />
    <axis xyz="0 0 0" />
  </joint>
  <link name="ob_camera_back_link">
    <inertial>
      <origin xyz="0.023316 0.000241 -0.013373" rpy="0 0 0" />
      <mass value="0.1" />
      <inertia ixx="1.5e-05" ixy="1e-06" ixz="-1e-06" iyy="0.000127" iyz="0.0" izz="0.000127" />
    </inertial>
    <visual>
      <origin xyz="0 0 0" rpy="0 0 0" />
      <geometry>
        <mesh filename="package://tiangong2pro_urdf/meshes/camera_body_back_link.STL" />
      </geometry>
      <material name="">
        <color rgba="0.752941176470588 0.752941176470588 0.752941176470588 1" />
      </material>
    </visual>
    <collision>
      <origin xyz="0 0 0" rpy="0 0 0" />
      <geometry>
        <mesh filename="package://tiangong2pro_urdf/meshes/camera_body_back_link.STL" />
      </geometry>
    </collision>
  </link>
  <joint name="camera_body_back_joint" type="fixed">
    <origin xyz="-0.11363 0.02375 0.2746" rpy="2.0071 0 -1.5708" />
    <parent link="waist_yaw_link" />
    <child link="ob_camera_back_link" />
    <axis xyz="0 0 0" />
  </joint>
  <link name="imu">
    <inertial>
      <origin xyz="-0.006331 -0.007725 -0.008045" rpy="0 0 0" />
      <mass value="0.02" />
      <inertia ixx="2e-06" ixy="0.0" ixz="0.0" iyy="3e-06" iyz="0.0" izz="4e-06" />
    </inertial>
    <visual>
      <origin xyz="0 0 0" rpy="0 0 0" />
      <geometry>
        <mesh filename="package://tiangong2pro_urdf/meshes/imu_link.STL" />
      </geometry>
      <material name="">
        <color rgba="0.752941176470588 0.752941176470588 0.752941176470588 1" />
      </material>
    </visual>
    <collision>
      <origin xyz="0 0 0" rpy="0 0 0" />
      <geometry>
        <mesh filename="package://tiangong2pro_urdf/meshes/imu_link.STL" />
      </geometry>
    </collision>
  </link>
  <joint name="imu_joint" type="fixed">
    <origin xyz="0.0499 -0.0358 -0.03194" rpy="0 0 0" />
    <parent link="pelvis" />
    <child link="imu" />
    <axis xyz="0 0 0" />
  </joint>
</robot>